<?xml version="1.0"?>

<robot name="jaime" xmlns:xacro="http://www.ros.org/wiki/xacro">

<xacro:property name="ancho" value="0.2">

</xacro:property>
  <material name="blue">
    <color rgba="0 0 0.8 1"/>
  </material>
  <material name="black">
    <color rgba="0 0 0 1"/>
  </material>
  <material name="white">
    <color rgba="1 1 1 1"/>
  </material>

  <link name="base_link">
    <visual>
      <geometry>
        <mesh filename="package://jaime/meshes_jaime/base_segment.stl" scale="0.001 0.001 0.001"/>
      </geometry>
      <material name="white"/>
      <origin xyz="0.0 0.0 0" rpy="0.0 0.0 0.0"/>
    </visual>

    <collision>
    <origin xyz="0.0 0.0 0.05" rpy="0.0 0.0 0.0"/>
    <geometry>
      <cylinder radius="0.175" length="0.1"/>
    </geometry>
    </collision>

    <collision>
    <origin xyz="0.0 0.0 0.2" rpy="0.0 0.0 0.0"/>
    <geometry>
      <box size="0.2 0.1 0.2"/>
    </geometry>
    </collision>

    <collision>
    <origin xyz="-0.1 0.0 0.45" rpy="0 -0.3 0.0"/>
    <geometry>
      <box size="0.1 0.1 0.35"/>
    </geometry>
    </collision>

    <collision>
    <origin xyz="-0.15 0.0 0.65" rpy="0 0 0.0"/>
    <geometry>
      <box size="0.15 0.1 0.1"/>
    </geometry>
    </collision>

    <inertial>
      <origin rpy="0 0 0" xyz="-0.048761000000000006 0.0 0.271195"/>
      <mass value="1.6895311238439816"/>
      <inertia ixx="0.08719578772036611" ixy="5.4784475406747093e-17" ixz="0.022449725248199624" iyy="0.09476693416632961" iyz="-2.4061783957761517e-16" izz="0.015163560157224643"/>
    </inertial>
    
  </link>
   
  <link name="entre_cuello_link">
  <origin xyz="0 0.0 -0.02" rpy="0.0 0.0 0.0"/>
    <visual>
      <geometry>
        <mesh filename="package://jaime/meshes_jaime/middle_link.stl" scale="0.001 0.001 0.001"/>
      </geometry>
      <material name="blue"/>
      <origin xyz="0 0.0 -0.02" rpy="0.0 0.0 0.0"/>
    </visual>

    <collision>
    <origin xyz="-0.01 0.0 0.066" rpy="0 -0.2 0.0"/>
    <geometry>
      <box size="0.05 0.1 0.135"/>
    </geometry>
    </collision>

    <inertial>
      <origin rpy="0 0 0" xyz="-0.016311 0.0 0.099931"/>
      <mass value="0.04935881321854115"/>
      <inertia ixx="0.00013683358492508186" ixy="1.0391185824431925e-20" ixz="1.6864941381036664e-05" iyy="0.0001101218997112331" iyz="4.551194773697158e-20" izz="4.4150842757921956e-05"/>
    </inertial>

  </link>

  <link name="cuello_link">
  <origin xyz="0. 0.0 0" rpy="0.0 0.0 0.0"/>
    <visual>
      <geometry>
        <mesh filename="package://jaime/meshes_jaime/middle_segment.stl" scale="0.001 0.001 0.001"/>
      </geometry>
      <material name="white"/>
      <origin xyz="0 0.0 0" rpy="0.0 0.0 0.0"/>
    </visual>

    <collision>
    <origin xyz="-0.0 0.0 0.09" rpy="0 0 0.0"/>
    <geometry>
      <box size="0.12 0.1 0.28"/>
    </geometry>
    </collision>

    <inertial>
      <origin rpy="0 0 0" xyz="-0.008064 0.0 0.08278"/>
      <mass value="0.32942"/>
      <inertia ixx="0.0016762858507607943" ixy="-4.8489364878642617e-20" ixz="-0.00011633194117814697" iyy="0.0018413198294705605" iyz="-1.2568953790911309e-19" izz="0.00030225037441020564"/>
    </inertial>
  </link>

  <link name="entre_cuello_2_link">
  <origin xyz="0.0 0.0 0.0" rpy="0.0 0.0 0.0"/>
    <visual>
      <geometry>
        <mesh filename="package://jaime/meshes_jaime/upper_link.stl" scale="0.001 0.001 0.001"/>
      </geometry>
      <material name="blue"/>
      <origin xyz="0.0 0.0 0" rpy="0.0 0.0 0.0"/>
    </visual>

    <collision>
    <origin xyz="0.03 0.0 0.08" rpy="0 0.3 0.0"/>
    <geometry>
      <box size="0.03 0.05 0.2"/>
    </geometry>
    </collision>

    <inertial>
      <origin rpy="0 0 0" xyz="0.034091 0.0 0.104876"/>
      <mass value="0.019952905767724887"/>
      <inertia ixx="7.401008323582294e-05" ixy="4.2619599656491147e-20" ixz="-2.1641569166888918e-05" iyy="6.762990364652787e-05" iyz="1.346217893341262e-19" izz="2.3087743207129134e-05"/>
    </inertial>

  </link>

  <link name="cuello_2_link">
  <origin xyz="0 0.0 0" rpy="0.0 0.0 0.0"/>
    <visual>
      <geometry>
        <mesh filename="package://jaime/meshes_jaime/upper_segment.stl" scale="0.001 0.001 0.001"/>
      </geometry>
      <material name="white"/>
      <origin xyz="0.0 0.0 0.0" rpy="0.0 0.0 0.0"/>
    </visual>

    <collision>
    <origin xyz="-0.02 0.0 0.03" rpy="0 0.6 0.0"/>
    <geometry>
      <box size="0.08 0.05 0.1"/>
    </geometry>
    </collision>

    <collision>
    <origin xyz="0.03 0.0 0.1" rpy="0 0.6 0.0"/>
    <geometry>
      <box size="0.05 0.05 0.1"/>
    </geometry>
    </collision>

    <inertial>
      <origin rpy="0 0 0" xyz="-0.003079 9.001e-10 0.04753"/>
      <mass value="0.07524443531369857"/>
      <inertia ixx="0.00010323130575479441" ixy="-4.678798365483059e-13" ixz="-5.295549059114918e-05" iyy="0.0001405766236174683" iyz="-2.5520718357180323e-12" izz="5.971848095580196e-05"/>
    </inertial>

  </link>

  <link name="cuello_3_link">
  <origin xyz="0 0.0 0" rpy="0.0 0.0 0.0"/>
    <visual>
      <geometry>
        <mesh filename="package://jaime/meshes_jaime/top_segment.stl" scale="0.001 0.001 0.001"/>
      </geometry>
      <material name="white"/>
      <origin xyz="0.0 0.0 0.0" rpy="0.0 0.0 0.0"/>
    </visual>

    <collision>
    <origin xyz="0.05 0.0 0.06" rpy="0 0.785 0.0"/>
    <geometry>
      <box size="0.05 0.05 0.16"/>
    </geometry>
    </collision>

    <inertial>
      <origin rpy="0 0 0" xyz="-0.003079 9.001e-10 0.04753"/>
      <mass value="0.050927614310487625"/>
      <inertia ixx="5.342337042769748e-05" ixy="-1.9238368188254434e-20" ixz="-5.142424748971835e-05" iyy="0.00011356719668945245" iyz="-4.589475851232928e-21" izz="6.775750723831377e-05"/>
    </inertial>

  </link>

  <link name="Tablet">
    <visual>
      <geometry>
        <mesh filename="package://jaime/meshes_jaime/tablet.stl" scale="0.001 0.001 0.001"/>
      </geometry>
      <material name="black"/>
      <origin xyz="0.0 0.0 0.0" rpy="1.57 0.785 0.0"/>
    </visual>

    <collision>
    <origin xyz="0.0 0.0 0.0" rpy="0 -0.785 0.0"/>
    <geometry>
      <box size="0.01 0.17 0.25"/>
    </geometry>
    </collision>

    <inertial>
      <origin rpy="1.414 0.785 0" xyz="0 0.6 0"/>
      <mass value="0"/>
      <inertia ixx= "0.00023852500001664517" ixy="0" ixz="0" iyy="0.00043338531058851275" iyz="0" izz="0.0004993545010816019"/>
    </inertial>
    
  </link>



  <joint name="primero" type="revolute">
    <parent link="base_link"/>
    <child link="entre_cuello_link"/>
    <axis xyz="0 1 0"/>
    <origin xyz="-0.158 0.0 0.68518" rpy="0.0 0 0.0"/>
    <limit upper="0.7" lower="0" velocity="2" effort="1"/>
  </joint>

  <joint name="segundo" type="revolute">
    <parent link="entre_cuello_link"/>
    <child link="cuello_link"/>
    <axis xyz="0 1 0"/>
    <origin xyz="-0.02 0.0 0.12" rpy="0.0 0 0.0"/>
    <limit upper="0.7" lower="0" velocity="2" effort="1"/>
    <mimic joint="primero" multiplier="1" offset="0" />
  </joint>

  <joint name="tercero" type="revolute">
    <parent link="cuello_link"/>
    <child link="entre_cuello_2_link"/>
    <axis xyz="0 1 0"/>
    <origin xyz="0.03 0.0 0.18" rpy="0.0 0 0.0"/>
    <limit upper="0.7" lower="0" velocity="2" effort="1"/>
  </joint>

  <joint name="cuarto" type="revolute">
    <parent link="entre_cuello_2_link"/>
    <child link="cuello_2_link"/>
    <axis xyz="0 1 0"/>
    <origin xyz="0.055 0.0 0.16" rpy="0.0 0 0.0"/>
    <limit upper="0.7" lower="0" velocity="2" effort="1"/>
    <mimic joint="tercero" multiplier="1" offset="0" />
  </joint>

  <joint name="quinto" type="revolute">
    <parent link="cuello_2_link"/>
    <child link="cuello_3_link"/>
    <axis xyz="0 1 0"/>
    <origin xyz="0.063 0.0 0.138" rpy="0.0 0 0.0"/>
    <limit upper="0.785" lower="0" velocity="2" effort="1"/>
  </joint>

   <joint name="tablet" type="fixed">
    <parent link="cuello_3_link"/>
    <child link="Tablet"/>
    <origin xyz="0.13 0.0 0.11" rpy="0.0 0 0.0"/>
  </joint>



  <transmission name="tran1">
    <type>transmission_interface/SimpleTransmission</type>
    <joint name="primero">
      <hardwareInterface>EffortJointInterface</hardwareInterface>
    </joint>
    <actuator name="motor1">
      <hardwareInterface>EffortJointInterface</hardwareInterface>
      <mechanicalReduction>1</mechanicalReduction>
    </actuator>
  </transmission>

  

  <transmission name="tran2">
    <type>transmission_interface/SimpleTransmission</type>
    <joint name="segundo">
      <hardwareInterface>EffortJointInterface</hardwareInterface>
    </joint>
    <actuator name="motor2">
      <hardwareInterface>EffortJointInterface</hardwareInterface>
      <mechanicalReduction>1</mechanicalReduction>
    </actuator>
  </transmission>
  
  <transmission name="tran3">
    <type>transmission_interface/SimpleTransmission</type>
    <joint name="tercero">
      <hardwareInterface>EffortJointInterface</hardwareInterface>
    </joint>
    <actuator name="motor3">
      <hardwareInterface>EffortJointInterface</hardwareInterface>
      <mechanicalReduction>1</mechanicalReduction>
    </actuator>
  </transmission>

  <transmission name="tran4">
    <type>transmission_interface/SimpleTransmission</type>
    <joint name="cuarto">
      <hardwareInterface>EffortJointInterface</hardwareInterface>
    </joint>
    <actuator name="motor4">
      <hardwareInterface>EffortJointInterface</hardwareInterface>
      <mechanicalReduction>1</mechanicalReduction>
    </actuator>
  </transmission>

  <transmission name="tran5">
    <type>transmission_interface/SimpleTransmission</type>
    <joint name="quinto">
      <hardwareInterface>EffortJointInterface</hardwareInterface>
    </joint>
    <actuator name="motor5">
      <hardwareInterface>EffortJointInterface</hardwareInterface>
      <mechanicalReduction>1</mechanicalReduction>
    </actuator>
  </transmission>




  <gazebo>
    <plugin name="gazebo_ros_control" filename="libgazebo_ros_control.so">
      <robotNamespace>/jaime</robotNamespace>
    </plugin>
  </gazebo>


</robot>

