<?xml version="1.0"?>

<robot name="jaime" xmlns:xacro="http://www.ros.org/wiki/xacro">

<xacro:property name="ancho" value="0.2">

</xacro:property>
  <material name="blue">
    <color rgba="0 0 0.8 1"/>
  </material>
  <material name="black">
    <color rgba="0 0 0 1"/>
  </material>
  <material name="white">
    <color rgba="1 1 1 1"/>
  </material>

  <link name="base_link">
    <visual>
      <geometry>
        <mesh filename="package://jaime/meshes_jaime/base_segment.stl" scale="0.001 0.001 0.001"/>
      </geometry>
      <material name="white"/>
      <origin xyz="0.0 0.0 0" rpy="0.0 0.0 0.0"/>
    </visual>

    <collision>
    <origin xyz="0.0 0.0 0.05" rpy="0.0 0.0 0.0"/>
    <geometry>
      <cylinder radius="0.175" length="0.1"/>
    </geometry>
    </collision>

    <collision>
    <origin xyz="0.0 0.0 0.2" rpy="0.0 0.0 0.0"/>
    <geometry>
      <box size="0.2 0.1 0.2"/>
    </geometry>
    </collision>

    <collision>
    <origin xyz="-0.1 0.0 0.45" rpy="0 -0.3 0.0"/>
    <geometry>
      <box size="0.1 0.1 0.35"/>
    </geometry>
    </collision>

    <collision>
    <origin xyz="-0.15 0.0 0.65" rpy="0 0 0.0"/>
    <geometry>
      <box size="0.15 0.1 0.1"/>
    </geometry>
    </collision>

    <inertial>
      <mass value="1.6895311238439816"/>
      <inertia ixx="0.21223169365626263" ixy="0.0" ixz="0.04500324371243572" iyy="2.2194518064627823e-10" iyz="0" izz="1.9144792220944774e-11"/>
    </inertial>
    
  </link>
   
  <link name="entre_cuello_link">
  <origin xyz="0 0.0 -0.02" rpy="0.0 0.0 0.0"/>
    <visual>
      <geometry>
        <mesh filename="package://jaime/meshes_jaime/middle_link.stl" scale="0.001 0.001 0.001"/>
      </geometry>
      <material name="blue"/>
      <origin xyz="0 0.0 -0.02" rpy="0.0 0.0 0.0"/>
    </visual>

    <collision>
    <origin xyz="-0.01 0.0 0.066" rpy="0 -0.2 0.0"/>
    <geometry>
      <box size="0.05 0.1 0.135"/>
    </geometry>
    </collision>

    <inertial>
      <mass value="0.04935881321854115"/>
      <inertia ixx="0.000629936398116401" ixy="0" ixz="0.0" iyy="0.0006163253483259048" iyz="0.0" izz="5.729401271186983e-05"/>
    </inertial>

  </link>

  <link name="cuello_link">
  <origin xyz="0. 0.0 0" rpy="0.0 0.0 0.0"/>
    <visual>
      <geometry>
        <mesh filename="package://jaime/meshes_jaime/middle_segment.stl" scale="0.001 0.001 0.001"/>
      </geometry>
      <material name="white"/>
      <origin xyz="0 0.0 0" rpy="0.0 0.0 0.0"/>
    </visual>

    <collision>
    <origin xyz="-0.0 0.0 0.09" rpy="0 0 0.0"/>
    <geometry>
      <box size="0.12 0.1 0.28"/>
    </geometry>
    </collision>

    <inertial>
      <mass value="0.32942"/>
      <inertia ixx="0.003933593389453394" ixy="0.0" ixz="0.00010357158199955683" iyy="0.0041198946334608105" iyz="0.0" izz=" 0.00032368777783023714"/>
    </inertial>
  </link>

  <link name="entre_cuello_2_link">
  <origin xyz="0.0 0.0 0.0" rpy="0.0 0.0 0.0"/>
    <visual>
      <geometry>
        <mesh filename="package://jaime/meshes_jaime/upper_link.stl" scale="0.001 0.001 0.001"/>
      </geometry>
      <material name="blue"/>
      <origin xyz="0.0 0.0 0" rpy="0.0 0.0 0.0"/>
    </visual>

    <collision>
    <origin xyz="0.03 0.0 0.08" rpy="0 0.3 0.0"/>
    <geometry>
      <box size="0.03 0.05 0.2"/>
    </geometry>
    </collision>

    <inertial>
      <mass value="0.019952905767724887"/>
      <inertia ixx="0.0002934457265769784" ixy="0.0" ixz="0.0" iyy="0.00031028940069271745" iyz="0.0" izz="4.627756928768699e-05"/>
    </inertial>

  </link>

  <link name="cuello_2_link">
  <origin xyz="0 0.0 0" rpy="0.0 0.0 0.0"/>
    <visual>
      <geometry>
        <mesh filename="package://jaime/meshes_jaime/upper_segment.stl" scale="0.001 0.001 0.001"/>
      </geometry>
      <material name="white"/>
      <origin xyz="0.0 0.0 0.0" rpy="0.0 0.0 0.0"/>
    </visual>

    <collision>
    <origin xyz="-0.02 0.0 0.03" rpy="0 0.6 0.0"/>
    <geometry>
      <box size="0.08 0.05 0.1"/>
    </geometry>
    </collision>

    <collision>
    <origin xyz="0.03 0.0 0.1" rpy="0 0.6 0.0"/>
    <geometry>
      <box size="0.05 0.05 0.1"/>
    </geometry>
    </collision>

    <inertial>
      <mass value="0.07524443531369857"/>
      <inertia ixx="0.00027319929001361535" ixy="0.0" ixz="0.0" iyy="0.00031126769489640935" iyz="0.0" izz="6.044156797592207e-05"/>
    </inertial>

  </link>

  <link name="cuello_3_link">
  <origin xyz="0 0.0 0" rpy="0.0 0.0 0.0"/>
    <visual>
      <geometry>
        <mesh filename="package://jaime/meshes_jaime/top_segment.stl" scale="0.001 0.001 0.001"/>
      </geometry>
      <material name="white"/>
      <origin xyz="0.0 0.0 0.0" rpy="0.0 0.0 0.0"/>
    </visual>

    <collision>
    <origin xyz="0.05 0.0 0.06" rpy="0 0.785 0.0"/>
    <geometry>
      <box size="0.05 0.05 0.16"/>
    </geometry>
    </collision>

    <inertial>
      <mass value="0.050927614310487625"/>
      <inertia ixx="0.00017247752156394368" ixy="0.0" ixz="0.0" iyy="0.0003254742281152397" iyz="0.0" izz="0.00016065292205845016"/>
    </inertial>

  </link>

  <link name="Tablet">
    <visual>
      <geometry>
        <mesh filename="package://jaime/meshes_jaime/tablet.stl" scale="0.001 0.001 0.001"/>
      </geometry>
      <material name="black"/>
      <origin xyz="0.0 0.0 0.0" rpy="1.57 0.785 0.0"/>
    </visual>

    <collision>
    <origin xyz="0.0 0.0 0.0" rpy="0 -0.785 0.0"/>
    <geometry>
      <box size="0.01 0.17 0.25"/>
    </geometry>
    </collision>

    <inertial>
      <mass value="0.1"/>
      <inertia ixx="0.1" ixy="0.0" ixz="0.0" iyy="0.1" iyz="0.0" izz="0.1"/>
    </inertial>
    
  </link>



  <joint name="primero" type="revolute">
    <parent link="base_link"/>
    <child link="entre_cuello_link"/>
    <axis xyz="0 1 0"/>
    <origin xyz="-0.158 0.0 0.68518" rpy="0.0 0 0.0"/>
    <limit upper="0.7" lower="0" velocity="2" effort="1"/>
  </joint>

  <joint name="segundo" type="revolute">
    <parent link="entre_cuello_link"/>
    <child link="cuello_link"/>
    <axis xyz="0 1 0"/>
    <origin xyz="-0.02 0.0 0.12" rpy="0.0 0 0.0"/>
    <limit upper="0.7" lower="0" velocity="2" effort="1"/>
    <mimic joint="primero" multiplier="1" offset="0" />
  </joint>

  <joint name="tercero" type="revolute">
    <parent link="cuello_link"/>
    <child link="entre_cuello_2_link"/>
    <axis xyz="0 1 0"/>
    <origin xyz="0.03 0.0 0.18" rpy="0.0 0 0.0"/>
    <limit upper="0.7" lower="0" velocity="2" effort="1"/>
  </joint>

  <joint name="cuarto" type="revolute">
    <parent link="entre_cuello_2_link"/>
    <child link="cuello_2_link"/>
    <axis xyz="0 1 0"/>
    <origin xyz="0.055 0.0 0.16" rpy="0.0 0 0.0"/>
    <limit upper="0.7" lower="0" velocity="2" effort="1"/>
    <mimic joint="tercero" multiplier="1" offset="0" />
  </joint>

  <joint name="quinto" type="revolute">
    <parent link="cuello_2_link"/>
    <child link="cuello_3_link"/>
    <axis xyz="0 1 0"/>
    <origin xyz="0.063 0.0 0.138" rpy="0.0 0 0.0"/>
    <limit upper="0.785" lower="0" velocity="2" effort="1"/>
  </joint>

   <joint name="tablet" type="fixed">
    <parent link="cuello_3_link"/>
    <child link="Tablet"/>
    <origin xyz="0.13 0.0 0.11" rpy="0.0 0 0.0"/>
  </joint>



  <transmission name="primero_trans">
  <type>transmission_interface/SimpleTransmission</type>
  <joint name="primero">
    <hardwareInterface>hardware_interface/PositionJointInterface</hardwareInterface>
  </joint>
  <actuator name="primero_motor">
    <mechanicalReduction>1</mechanicalReduction>
    <hardwareInterface>hardware_interface/PositionJointInterface</hardwareInterface>
  </actuator>
  </transmission>

  

  <transmission name="segundo_trans">
  <type>transmission_interface/SimpleTransmission</type>
  <joint name="segundo">
    <hardwareInterface>hardware_interface/PositionJointInterface</hardwareInterface>
  </joint>
  <actuator name="segundo_motor">
    <mechanicalReduction>1</mechanicalReduction>
    <hardwareInterface>hardware_interface/PositionJointInterface</hardwareInterface>
  </actuator>
  </transmission>
  
  <transmission name="tercero_trans">
  <type>transmission_interface/SimpleTransmission</type>
  <joint name="tercero">
    <hardwareInterface>hardware_interface/PositionJointInterface</hardwareInterface>
  </joint>
  <actuator name="tercero_motor">
    <mechanicalReduction>1</mechanicalReduction>
    <hardwareInterface>hardware_interface/PositionJointInterface</hardwareInterface>
  </actuator>
  </transmission>

  <transmission name="cuarto_trans">
  <type>transmission_interface/SimpleTransmission</type>
  <joint name="cuarto">
    <hardwareInterface>hardware_interface/PositionJointInterface</hardwareInterface>
  </joint>
  <actuator name="cuarto_motor">
    <mechanicalReduction>1</mechanicalReduction>
    <hardwareInterface>hardware_interface/PositionJointInterface</hardwareInterface>
  </actuator>
  </transmission>

  <transmission name="quinto_trans">
  <type>transmission_interface/SimpleTransmission</type>
  <joint name="quinto">
    <hardwareInterface>hardware_interface/PositionJointInterface</hardwareInterface>
  </joint>
  <actuator name="quinto_motor">
    <mechanicalReduction>1</mechanicalReduction>
    <hardwareInterface>hardware_interface/PositionJointInterface</hardwareInterface>
  </actuator>
  </transmission>




  <gazebo>
    <plugin name="gazebo_ros_control" filename="libgazebo_ros_control.so">
      <robotNamespace>/</robotNamespace>
    </plugin>
  </gazebo>


</robot>

